Workbook

Sheet FSM Forecast
C2: ="Financial Statement Model for "&D5 -> Financial Statement Model for Micron
C3: $ in millions except per share
C5: Company name | D5: Micron
C6: Ticker | D6: MU
C7: Circ break 1=off, 0=on | D7: 1
C8: Latest closing share price date | D8: 46168
C9: Latest closing share price | D9: 895.88
C10: Latest fiscal year end date | D10: 45897
C11: Shares outstanding (millions) | D11: 1122.466
C12: Active Case | D12: Base Case
B14: x | C14: INCOME STATEMENT
C15: Fiscal year | D15: =E15-1 -> 2023 | E15: =F15-1 -> 2024 | F15: 2025 | G15: 2026 | H15: =G15+1 -> 2027 | I15: =H15+1 -> 2028 | J15: =I15+1 -> 2029 | K15: =J15+1 -> 2030
C16: Fiscal year end date | D16: =DATE(2024,8,29)-364 -> 45169 | E16: =DATE(2025,8,28)-364 -> 45533 | F16: =D10 -> 45897 | G16: =DATE(2025,8,28)+364 -> 46261 | H16: =DATE(2026,8,27)+364 -> 46625 | I16: =DATE(2027,8,26)+371 -> 46996 | J16: =DATE(2028,8,31)+364 -> 47360 | K16: =DATE(2029,8,30)+364 -> 47724
C18: Revenue | D18: 15540 | E18: 25111 | F18: 37378 | G18: =F18*(1+G39) -> 111252.28 | H18: =G18*(1+H39) -> 158866.68 | I18: =H18*(1+I39) -> 159891.88 | J18: =I18*(1+J39) -> 149898.64 | K18: =J18*(1+K39) -> 161890.53
C19: Cost of sales (enter as -) | D19: -16956 | E19: -19498 | F19: -22505 | G19: =G20-G18 -> -27813.071 | H19: =H20-H18 -> -31773.336 | I19: =I20-I18 -> -55962.157 | J19: =J20-J18 -> -67454.386 | K19: =K20-K18 -> -80945.263
C20: Gross Profit | D20: =SUM(D18:D19) -> -1416 | E20: =SUM(E18:E19) -> 5613 | F20: =SUM(F18:F19) -> 14873 | G20: =G18*G40 -> 83439.213 | H20: =H18*H40 -> 127093.35 | I20: =I18*I40 -> 103929.72 | J20: =J18*J40 -> 82444.25 | K20: =K18*K40 -> 80945.263
C21: Research & development (enter as -) | D21: -3114 | E21: -3430 | F21: -3798 | G21: =-G18*G41 -> -9790.201 | H21: =-H18*H41 -> -14679.281 | I21: =-I18*I41 -> -14710.053 | J21: =-J18*J41 -> -13790.674 | K21: =-K18*K41 -> -14893.928
C22: Selling, general & administrative (enter as -) | D22: -920 | E22: -1129 | F22: -1205 | G22: =-(G18*G42) -> -2781.3071 | H22: =-(H18*H42) -> -3971.667 | I22: =-(I18*I42) -> -3997.297 | J22: =-(J18*J42) -> -3747.4659 | K22: =-(K18*K42) -> -4047.2632
C23: Restructuring & asset impairments | D23: -171 | E23: -1 | F23: -39 | G23: 0 | H23: 0 | I23: 0 | J23: 0 | K23: 0
C24: Other operating income (expense), net | D24: -124 | E24: 251 | F24: -61 | G24: 0 | H24: 0 | I24: 0 | J24: 0 | K24: 0
C25: Operating profit (EBIT) | D25: =SUM(D20:D24) -> -5745 | E25: =SUM(E20:E24) -> 1304 | F25: =SUM(F20:F24) -> 9770 | G25: =SUM(G20:G22) -> 70867.705 | H25: =SUM(H20:H22) -> 108442.4 | I25: =SUM(I20:I22) -> 85222.371 | J25: =SUM(J20:J22) -> 64906.109 | K25: =SUM(K20:K22) -> 62004.072
C26: Interest income | D26: 468 | E26: 529 | F26: 496 | G26: =G170 -> 914.5455 | H26: =H170 -> 2613.4693 | I26: =I170 -> 5083.8373 | J26: =J170 -> 7288.7902 | K26: =K170 -> 9190.9367
C27: Interest expense (enter as -) | D27: -388 | E27: -562 | F27: -477 | G27: =-G153 -> -619.8925 | H27: =-H153 -> -423.3925 | I27: =-I153 -> -318.3925 | J27: =-J153 -> -213.3925 | K27: =-K153 -> -108.3925
C28: Other expense, net (enter as -) | D28: 7 | E28: -31 | F28: -135 | G28: =F28 -> -135 | H28: =G28 -> -135 | I28: =H28 -> -135 | J28: =I28 -> -135 | K28: =J28 -> -135
C29: Pretax profit | D29: =SUM(D25:D28) -> -5658 | E29: =SUM(E25:E28) -> 1240 | F29: =SUM(F25:F28) -> 9654 | G29: =SUM(G25:G28) -> 71027.358 | H29: =SUM(H25:H28) -> 110497.47 | I29: =SUM(I25:I28) -> 89852.816 | J29: =SUM(J25:J28) -> 71846.507 | K29: =SUM(K25:K28) -> 70951.616
C30: Taxes (enter expense as -) | D30: -177 | E30: -451 | F30: -1124 | G30: =-G29*G44 -> -11719.514 | H30: =-H29*H44 -> -18232.083 | I30: =-I29*I44 -> -14825.715 | J30: =-J29*J44 -> -11854.674 | K30: =-K29*K44 -> -11707.017
C31: Net income | D31: =SUM(D29:D30) -> -5835 | E31: =SUM(E29:E30) -> 789 | F31: =SUM(F29:F30) -> 8530 | G31: =SUM(G29:G30) -> 59307.844 | H31: =SUM(H29:H30) -> 92265.391 | I31: =SUM(I29:I30) -> 75027.101 | J31: =SUM(J29:J30) -> 59991.833 | K31: =SUM(K29:K30) -> 59244.599
C33: Depreciation & amortization | D33: 7756 | E33: 7780 | F33: 8352 | G33: =G117 -> 15040.649 | H33: =H117 -> 22612.893 | I33: =I117 -> 27082.589 | J33: =J117 -> 29051.36 | K33: =K117 -> 31044.614
C34: EBITDA | D34: =D33+D25 -> 2011 | E34: =E33+E25 -> 9084 | F34: =F33+F25 -> 18122 | G34: =G33+G25 -> 85908.354 | H34: =H33+H25 -> 131055.29 | I34: =I33+I25 -> 112304.96 | J34: =J33+J25 -> 93957.469 | K34: =K33+K25 -> 93048.686
C35: Stock based compensation | D35: 596 | E35: 833 | F35: 972 | G35: =F35*(1+G43) -> 1069.2 | H35: =G35*(1+H43) -> 1176.12 | I35: =H35*(1+I43) -> 1293.732 | J35: =I35*(1+J43) -> 1423.1052 | K35: =J35*(1+K43) -> 1565.4157
C36: Adjusted EBITDA | D36: =SUM(D34:D35) -> 2607 | E36: =SUM(E34:E35) -> 9917 | F36: =SUM(F34:F35) -> 19094 | G36: =SUM(G34:G35) -> 86977.554 | H36: =SUM(H34:H35) -> 132231.41 | I36: =SUM(I34:I35) -> 113598.69 | J36: =SUM(J34:J35) -> 95380.574 | K36: =SUM(K34:K35) -> 94614.102
C38: Growth rates & margins
C39: Revenue growth | E39: =E18/D18-1 -> 0.61589447 | F39: =F18/E18-1 -> 0.48851101 | G39: =G220 -> 1.9764108 | H39: =H220 -> 0.42798579 | I39: =I220 -> 0.0064531855 | J39: =J220 -> -0.0625 | K39: =K220 -> 0.08
C40: Gross profit margin | D40: =D20/D18 -> -0.091119691 | E40: =E20/E18 -> 0.22352754 | F40: =F20/F18 -> 0.39790786 | G40: =G221 -> 0.75 | H40: =H221 -> 0.8 | I40: =I221 -> 0.65 | J40: =J221 -> 0.55 | K40: =K221 -> 0.5
C41: R&D % of sales | D41: =-(D21/D18) -> 0.2003861 | E41: =-(E21/E18) -> 0.13659352 | F41: =-(F21/F18) -> 0.10161057 | G41: =G222 -> 0.088 | H41: =H222 -> 0.0924 | I41: =I222 -> 0.092 | J41: =J222 -> 0.092 | K41: =K222 -> 0.092
C42: SG&A % of sales | D42: =-(D22/D18) -> 0.059202059 | E42: =-(E22/E18) -> 0.044960376 | F42: =-(F22/F18) -> 0.032238215 | G42: =G223 -> 0.025 | H42: =H223 -> 0.025 | I42: =I223 -> 0.025 | J42: =J223 -> 0.025 | K42: =K223 -> 0.025
C43: SBC Increase | E43: =(E35/D35)-1 -> 0.39765101 | F43: =(F35/E35)-1 -> 0.16686675 | G43: 0.1 | H43: 0.1 | I43: 0.1 | J43: 0.1 | K43: 0.1
C44: Tax rate | D44: N/M | E44: =-E30/E29 -> 0.36370968 | F44: =-F30/F29 -> 0.11642842 | G44: 0.165 | H44: 0.165 | I44: 0.165 | J44: 0.165 | K44: 0.165
B46: x | C46: BALANCE SHEET
C47: Fiscal year | E47: =F47-1 -> 2024 | F47: 2025 | G47: 2026 | H47: =G47+1 -> 2027 | I47: =H47+1 -> 2028 | J47: =I47+1 -> 2029 | K47: =J47+1 -> 2030
...

Sheet Revenue Build
C2: Price / volume build
C3: Fiscal year | E3: 2024 | F3: 2025 | G3: 2026 | H3: =G3+1 -> 2027 | I3: =H3+1 -> 2028 | J3: =I3+1 -> 2029 | K3: =J3+1 -> 2030
C4: Fiscal year end date | E4: =DATE(2025,8,28)-364 -> 45533 | F4: ='FSM Forecast'!D10 -> 45897 | G4: =DATE(2025,8,28)+364 -> 46261 | H4: =DATE(2026,8,27)+364 -> 46625 | I4: =DATE(2027,8,26)+371 -> 46996 | J4: =DATE(2028,8,31)+364 -> 47360 | K4: =DATE(2029,8,30)+364 -> 47724
C5: Revenue by product
C6: Core products
C8: DRAM | E8: 17600 | F8: 28580 | G8: =F8*(1+G22) -> 88269.33 | H8: =G8*(1+H22) -> 127107.84 | I8: =H8*(1+I22) -> 128887.34 | J8: =I8*(1+J22) -> 120831.89 | K8: =J8*(1+K22) -> 130498.44
C9: NAND | E9: 7230 | F9: 8500 | G9: =F9*(1+G23) -> 22100 | H9: =G9*(1+H23) -> 30498 | I9: =H9*(1+I23) -> 29735.55 | J9: =I9*(1+J23) -> 27877.078 | K9: =J9*(1+K23) -> 30107.244
C10: Total Revenue | E10: =SUM(E8:E9) -> 24830 | F10: =SUM(F8:F9) -> 37080 | G10: =SUM(G8:G9) -> 110369.33 | H10: =SUM(H8:H9) -> 157605.84 | I10: =SUM(I8:I9) -> 158622.89 | J10: =SUM(J8:J9) -> 148708.96 | K10: =SUM(K8:K9) -> 160605.68
C11: % growth | F11: =F10/E10-1 -> 0.49335481 | G11: =G10/F10-1 -> 1.9765191 | H11: =H10/G10-1 -> 0.42798579 | I11: =I10/H10-1 -> 0.0064531855 | J11: =J10/I10-1 -> -0.0625 | K11: =K10/J10-1 -> 0.08
C13: Bit Demand Growth
C14: DRAM | G14: 0.45 | H14: 0.2 | I14: 0.3 | J14: 0.25 | K14: 0.2
C15: NAND | G15: 0.3 | H15: 0.2 | I15: 0.3 | J15: 0.25 | K15: 0.2
C17: Average Selling Price Change
C18: DRAM | G18: 1.13 | H18: 0.2 | I18: -0.22 | J18: -0.25 | K18: -0.1
C19: NAND | G19: 1 | H19: 0.15 | I19: -0.25 | J19: -0.25 | K19: -0.1
C21: Revenue Growth
C22: DRAM | G22: =(1+G14)*(1+G18)-1 -> 2.0885 | H22: =(1+H14)*(1+H18)-1 -> 0.44 | I22: =(1+I14)*(1+I18)-1 -> 0.014 | J22: =(1+J14)*(1+J18)-1 -> -0.0625 | K22: =(1+K14)*(1+K18)-1 -> 0.08
C23: NAND | G23: =(1+G15)*(1+G19)-1 -> 1.6 | H23: =(1+H15)*(1+H19)-1 -> 0.38 | I23: =(1+I15)*(1+I19)-1 -> -0.025 | J23: =(1+J15)*(1+J19)-1 -> -0.0625 | K23: =(1+K15)*(1+K19)-1 -> 0.08

Sheet DCF
C2: Discounted Cash Flow Valuation
C3: $ in millions except per share
C4: Most recent fiscal year end | G4: Discount rate (WACC) | I4: =F51 -> 0.12647402 | J4: Link from WACC
C5: End of first fiscal year | D5: 45897 | G5: Share price (Public Co) | I5: ='FSM Forecast'!D9 -> 895.88
C6: Most recent quarter end date | G6: Share price date | I6: ='FSM Forecast'!D8 -> 46168
C7: Valuation date | D7: 46168 | G7: Midyear adjustment? | I7: 1
C8: Portion of First Year Cash Flows | D8: =1-YEARFRAC(D7,D5) -> 0.25555556
G9: Case active: | H9: ='FSM Forecast'!D12 -> Base Case
B10: x | C10: Unlevered Free Cash Flows
C11: Fiscal year | E11: 2025 | F11: 2026 | G11: =F11+1 -> 2027 | H11: =G11+1 -> 2028 | I11: =H11+1 -> 2029 | J11: =I11+1 -> 2030
C12: Fiscal year end date | E12: =D5 -> 45897 | F12: =DATE(2025,8,28)+364 -> 46261 | G12: =DATE(2026,8,27)+364 -> 46625 | H12: =DATE(2027,8,26)+371 -> 46996 | I12: =DATE(2028,8,31)+364 -> 47360 | J12: =DATE(2029,8,30)+364 -> 47724
C14: Revenue | E14: ='FSM Forecast'!F18 -> 37378 | F14: ='FSM Forecast'!G18 -> 111252.28 | G14: ='FSM Forecast'!H18 -> 158866.68 | H14: ='FSM Forecast'!I18 -> 159891.88 | I14: ='FSM Forecast'!J18 -> 149898.64 | J14: ='FSM Forecast'!K18 -> 161890.53
C15: % growth | F15: =F14/E14-1 -> 1.9764108 | G15: =G14/F14-1 -> 0.42798579 | H15: =H14/G14-1 -> 0.0064531855 | I15: =I14/H14-1 -> -0.0625 | J15: =J14/I14-1 -> 0.08
C16: EBITDA | E16: =E18+E25 -> 9770 | F16: =F18+F25 -> 85908.354 | G16: =G18+G25 -> 131055.29 | H16: =H18+H25 -> 112304.96 | I16: =I18+I25 -> 93957.469 | J16: =J18+J25 -> 93048.686
C17: % margin | E17: =E16/E14 -> 0.2613837 | F17: =F16/F14 -> 0.77219407 | G17: =G16/G14 -> 0.8249388 | H17: =H16/H14 -> 0.70238064 | I17: =I16/I14 -> 0.6268067 | J17: =J16/J14 -> 0.57476301
C18: EBIT | E18: ='FSM Forecast'!F25 -> 9770 | F18: ='FSM Forecast'!G25 -> 70867.705 | G18: ='FSM Forecast'!H25 -> 108442.4 | H18: ='FSM Forecast'!I25 -> 85222.371 | I18: ='FSM Forecast'!J25 -> 64906.109 | J18: ='FSM Forecast'!K25 -> 62004.072
C19: % margin | E19: =E18/E14 -> 0.2613837 | F19: =F18/F14 -> 0.637 | G19: =G18/G14 -> 0.6826 | H19: =H18/H14 -> 0.533 | I19: =I18/I14 -> 0.433 | J19: =J18/J14 -> 0.383
C21: Tax on EBIT | E21: =E22*E18 -> 1137.5057 | F21: =F22*F18 -> 11693.171 | G21: =G22*G18 -> 17892.996 | H21: =H22*H18 -> 14061.691 | I21: =I22*I18 -> 10709.508 | J21: =J22*J18 -> 10230.672
C22: Tax rate | E22: ='FSM Forecast'!F44 -> 0.11642842 | F22: ='FSM Forecast'!G44 -> 0.165 | G22: ='FSM Forecast'!H44 -> 0.165 | H22: ='FSM Forecast'!I44 -> 0.165 | I22: ='FSM Forecast'!J44 -> 0.165 | J22: ='FSM Forecast'!K44 -> 0.165
C23: NOPAT (aka EBIAT) | E23: =E18*(1-E22) -> 8632.4943 | F23: =F18*(1-F22) -> 59174.534 | G23: =G18*(1-G22) -> 90549.402 | H23: =H18*(1-H22) -> 71160.68 | I23: =I18*(1-I22) -> 54196.601 | J23: =J18*(1-J22) -> 51773.4
C25: Depreciation & amortization | F25: ='FSM Forecast'!G33 -> 15040.649 | G25: ='FSM Forecast'!H33 -> 22612.893 | H25: ='FSM Forecast'!I33 -> 27082.589 | I25: ='FSM Forecast'!J33 -> 29051.36 | J25: ='FSM Forecast'!K33 -> 31044.614
C26: Changes in net working capital | F26: =F32 -> -17352.049 | G26: =G32 -> -11152.97 | H26: =H32 -> 1145.777 | I26: =I32 -> 3049.3449 | J26: =J32 -> -2090.5701
C27: Capital expenditures | F27: ='FSM Forecast'!G108 -> 26000 | G27: ='FSM Forecast'!H108 -> 36000 | H27: ='FSM Forecast'!I108 -> 40000 | I27: ='FSM Forecast'!J108 -> 40000 | J27: ='FSM Forecast'!K108 -> 40000
C28: as % of revenue | F28: =F27/F14 -> 0.23370307 | G28: =G27/G14 -> 0.2266051 | H28: =H27/H14 -> 0.25016905 | I28: =I27/I14 -> 0.26684699 | J28: =J27/J14 -> 0.24708055
C30: Unlevered free cash flows (UFCF) | F30: =F23+F25+F26+F27 -> 82863.134 | G30: =G23+G25+G26+G27 -> 138009.32 | H30: =H23+H25+H26+H27 -> 139389.05 | I30: =I23+I25+I26+I27 -> 126297.31 | J30: =J23+J25+J26+J27 -> 120727.44
C32: Net working capital (WC Assets - WC liabilities) | F32: ='FSM Forecast'!G86+'FSM Forecast'!G87 -> -17352.049 | G32: ='FSM Forecast'!H86+'FSM Forecast'!H87 -> -11152.97 | H32: ='FSM Forecast'!I86+'FSM Forecast'!I87 -> 1145.777 | I32: ='FSM Forecast'!J86+'FSM Forecast'!J87 -> 3049.3449 | J32: ='FSM Forecast'!K86+'FSM Forecast'!K87 -> -2090.5701
B33: x | C33: as % of revenue | F33: =F32/F14 -> -0.15597027 | G33: =G32/G14 -> -0.070203332 | H33: =H32/H14 -> 0.0071659485 | I33: =I32/I14 -> 0.020342713 | J33: =J32/J14 -> -0.01291348
C35: Weighted Average Cost of Capital
C37: Risk free rate (Rf) | F37: 0.04263
C38: Equity Beta | F38: 1.7
C39: Equity risk premium (Rm - Rf) | F39: 0.05
C40: Cost of Equity (Ke) | F40: =F37+F38*F39 -> 0.12763
C42: Cost of debt | F42: ='FSM Forecast'!G164 -> 0.0525
C43: Tax rate | F43: ='FSM Forecast'!G44 -> 0.165
C44: After-tax Cost of Debt (Kdt) | F44: =F42*(1-F43) -> 0.0438375
C46: Percentage of Capital
C47: Debt | E47: ='FSM Forecast'!G161+'FSM Forecast'!G157 -> 14067 | F47: =E47/E49 -> 0.01379575
C48: Equity | E48: ='FSM Forecast'!D11*I5 -> 1005594.8 | F48: =E48/E49 -> 0.98620425
C49: Total capital | E49: =SUM(E47:E48) -> 1019661.8 | F49: =SUM(F47:F48) -> 1
C51: Weighted Average Cost of Capital | F51: =F40*F48+F44*F47 -> 0.12647402
...
